Workbook

Sheet Overview
A1: DecVAE revision: baseline parameter record
A2: Pre-training, fine-tuning and evaluation settings of DecVAE and the trained baselines (CoST, TF-C, TCL, CPC, FHVAE), with reference values and every deviation.
A3: Reference values were read from the reference repositories; line numbers point to those files. 'Config now' columns were read from config_files/ on the date below.
A4: Snapshot date: 2026-09-21
A6: Sheets
A7: Shared protocol | B7: Settings held constant across methods (the matched protocol).
A8: Pre-training | B8: Per-method parameters: reference value, agreed value, current config, deviation, rationale.
A9: Fine-tuning | B9: IEMOCAP transfer settings.
A10: Evaluation | B10: Metrics, factors, and which vector each method is evaluated on.
A11: Tracker | B11: Open implementation items found while recording the parameters.
A13: How to use
A14: Yellow cells | B14: Editable: agreed values, current config, rationale, status.
A15: Config check | B15: Formula: compares agreed vs config-now values. 'differs' = config still needs changing.
A16: Status | B16: Final / Decided (user) / To confirm / To fix / To implement (drop-down).
A17: Deviation | B17: Yes = differs from the reference implementation; filter on it for the reviewer-facing list.
A18: For the SI | B18: Hide the 'config now', 'Config check' and 'Status' columns and the Tracker sheet.
A20: Status by method (Pre-training sheet)
A21: Method | B21: Parameters | C21: Deviations | D21: Final | E21: Decided (user) | F21: To confirm | G21: To fix | H21: To implement
A22: DecVAE | B22: =COUNTIF('Pre-training'!$B$2:$B$106,A22) -> 13 | C22: =COUNTIFS('Pre-training'!$B$2:$B$106,A22,'Pre-training'!$M$2:$M$106,"Yes") -> 0 | D22: =COUNTIFS('Pre-training'!$B$2:$B$106,$A22,'Pre-training'!$O$2:$O$106,"Final") -> 11 | E22: =COUNTIFS('Pre-training'!$B$2:$B$106,$A22,'Pre-training'!$O$2:$O$106,"Decided (user)") -> 0 | F22: =COUNTIFS('Pre-training'!$B$2:$B$106,$A22,'Pre-training'!$O$2:$O$106,"To confirm") -> 2 | G22: =COUNTIFS('Pre-training'!$B$2:$B$106,$A22,'Pre-training'!$O$2:$O$106,"To fix") -> 0 | H22: =COUNTIFS('Pre-training'!$B$2:$B$106,$A22,'Pre-training'!$O$2:$O$106,"To implement") -> 0
A23: CoST | B23: =COUNTIF('Pre-training'!$B$2:$B$106,A23) -> 20 | C23: =COUNTIFS('Pre-training'!$B$2:$B$106,A23,'Pre-training'!$M$2:$M$106,"Yes") -> 7 | D23: =COUNTIFS('Pre-training'!$B$2:$B$106,$A23,'Pre-training'!$O$2:$O$106,"Final") -> 16 | E23: =COUNTIFS('Pre-training'!$B$2:$B$106,$A23,'Pre-training'!$O$2:$O$106,"Decided (user)") -> 0 | F23: =COUNTIFS('Pre-training'!$B$2:$B$106,$A23,'Pre-training'!$O$2:$O$106,"To confirm") -> 1 | G23: =COUNTIFS('Pre-training'!$B$2:$B$106,$A23,'Pre-training'!$O$2:$O$106,"To fix") -> 3 | H23: =COUNTIFS('Pre-training'!$B$2:$B$106,$A23,'Pre-training'!$O$2:$O$106,"To implement") -> 0
A24: TF-C | B24: =COUNTIF('Pre-training'!$B$2:$B$106,A24) -> 20 | C24: =COUNTIFS('Pre-training'!$B$2:$B$106,A24,'Pre-training'!$M$2:$M$106,"Yes") -> 7 | D24: =COUNTIFS('Pre-training'!$B$2:$B$106,$A24,'Pre-training'!$O$2:$O$106,"Final") -> 14 | E24: =COUNTIFS('Pre-training'!$B$2:$B$106,$A24,'Pre-training'!$O$2:$O$106,"Decided (user)") -> 1 | F24: =COUNTIFS('Pre-training'!$B$2:$B$106,$A24,'Pre-training'!$O$2:$O$106,"To confirm") -> 0 | G24: =COUNTIFS('Pre-training'!$B$2:$B$106,$A24,'Pre-training'!$O$2:$O$106,"To fix") -> 5 | H24: =COUNTIFS('Pre-training'!$B$2:$B$106,$A24,'Pre-training'!$O$2:$O$106,"To implement") -> 0
A25: TCL | B25: =COUNTIF('Pre-training'!$B$2:$B$106,A25) -> 16 | C25: =COUNTIFS('Pre-training'!$B$2:$B$106,A25,'Pre-training'!$M$2:$M$106,"Yes") -> 8 | D25: =COUNTIFS('Pre-training'!$B$2:$B$106,$A25,'Pre-training'!$O$2:$O$106,"Final") -> 9 | E25: =COUNTIFS('Pre-training'!$B$2:$B$106,$A25,'Pre-training'!$O$2:$O$106,"Decided (user)") -> 0 | F25: =COUNTIFS('Pre-training'!$B$2:$B$106,$A25,'Pre-training'!$O$2:$O$106,"To confirm") -> 1 | G25: =COUNTIFS('Pre-training'!$B$2:$B$106,$A25,'Pre-training'!$O$2:$O$106,"To fix") -> 5 | H25: =COUNTIFS('Pre-training'!$B$2:$B$106,$A25,'Pre-training'!$O$2:$O$106,"To implement") -> 1
A26: CPC | B26: =COUNTIF('Pre-training'!$B$2:$B$106,A26) -> 19 | C26: =COUNTIFS('Pre-training'!$B$2:$B$106,A26,'Pre-training'!$M$2:$M$106,"Yes") -> 10 | D26: =COUNTIFS('Pre-training'!$B$2:$B$106,$A26,'Pre-training'!$O$2:$O$106,"Final") -> 14 | E26: =COUNTIFS('Pre-training'!$B$2:$B$106,$A26,'Pre-training'!$O$2:$O$106,"Decided (user)") -> 0 | F26: =COUNTIFS('Pre-training'!$B$2:$B$106,$A26,'Pre-training'!$O$2:$O$106,"To confirm") -> 2 | G26: =COUNTIFS('Pre-training'!$B$2:$B$106,$A26,'Pre-training'!$O$2:$O$106,"To fix") -> 3 | H26: =COUNTIFS('Pre-training'!$B$2:$B$106,$A26,'Pre-training'!$O$2:$O$106,"To implement") -> 0
A27: FHVAE | B27: =COUNTIF('Pre-training'!$B$2:$B$106,A27) -> 17 | C27: =COUNTIFS('Pre-training'!$B$2:$B$106,A27,'Pre-training'!$M$2:$M$106,"Yes") -> 7 | D27: =COUNTIFS('Pre-training'!$B$2:$B$106,$A27,'Pre-training'!$O$2:$O$106,"Final") -> 14 | E27: =COUNTIFS('Pre-training'!$B$2:$B$106,$A27,'Pre-training'!$O$2:$O$106,"Decided (user)") -> 0 | F27: =COUNTIFS('Pre-training'!$B$2:$B$106,$A27,'Pre-training'!$O$2:$O$106,"To confirm") -> 1 | G27: =COUNTIFS('Pre-training'!$B$2:$B$106,$A27,'Pre-training'!$O$2:$O$106,"To fix") -> 2 | H27: =COUNTIFS('Pre-training'!$B$2:$B$106,$A27,'Pre-training'!$O$2:$O$106,"To implement") -> 0
A28: Total | B28: =SUM(B22:B27) -> 105 | C28: =SUM(C22:C27) -> 39 | D28: =SUM(D22:D27) -> 78 | E28: =SUM(E22:E27) -> 1 | F28: =SUM(F22:F27) -> 7 | G28: =SUM(G22:G27) -> 18 | H28: =SUM(H22:H27) -> 1
A30: Open tracker items by priority
A31: Critical | B31: =COUNTIFS(Tracker!$G$2:$G$20,A31,Tracker!$H$2:$H$20,"<>Done") -> 1
A32: High | B32: =COUNTIFS(Tracker!$G$2:$G$20,A32,Tracker!$H$2:$H$20,"<>Done") -> 8
A33: Medium | B33: =COUNTIFS(Tracker!$G$2:$G$20,A33,Tracker!$H$2:$H$20,"<>Done") -> 6
A34: Low | B34: =COUNTIFS(Tracker!$G$2:$G$20,A34,Tracker!$H$2:$H$20,"<>Done") -> 4
A36: Config rows still differing from the agreed value | B36: =COUNTIF('Pre-training'!$L$2:$L$106,"differs") -> 24

Sheet Shared protocol
A1: ID | B1: Category | C1: Setting | D1: SimVowels | E1: TIMIT | F1: IEMOCAP | G1: Applies to | H1: Source / rationale | I1: Status
A2: S-01 | B2: Data | C2: Max utterance duration | D2: 4.0 s | E2: 7.15 s | F2: 7.0 s | G2: All | H2: SI Table 3 / configs | I2: Final
A3: S-02 | B3: Data | C3: Min utterance duration | D3: 0 s | E3: 1 s (SI Table 3); configs hold 0.0 | F3: configs hold 0.0 | G3: All | H3: SI states 1 s for real data; configs use 0.0. Align. | I3: To confirm
A4: S-03 | B4: Data | C4: Splits | D4: train / dev / test caches (EWT, NoC 3) | E4: train / dev speakers / core test (NoC 4) | F4: transfer: fine-tune on IEMOCAP from SimVowels or TIMIT | G4: All | H4: config_files | I4: Final
A5: S-04 | B5: Data | C5: Evaluation data subset | D5: full | E5: trained baselines point to *_subset5pct caches; DecVAE / SSL / PCA / SFA use full | F5: trained baselines point to *_subset5pct | G5: All | H5: Final runs must use the same (full) sets for every method. | I5: To confirm
A6: S-05 | B6: Front-end | C6: Input features | D6: mel 80, mel_hops 4 (400-dim patch per frame), global norm | E6: same | F6: same | G6: All except TF-C (waveform) | H6: Methods p.21 L546-548; SI Tables 3, 6-8 | I6: Final
A7: S-06 | B7: Front-end | C7: Frame grid | D7: 25 ms window, 20 ms hop | E7: same | F7: same | G7: All | H7: DecVAE conv geometry; labels used without realignment | I7: Final
A8: S-07 | B8: Front-end | C8: Decomposition component fed to baselines | D8: 0 (original signal) | E8: 0 | F8: 0 | G8: Trained baselines | H8: baseline_component | I8: Final
A9: S-08 | B9: Latent | C9: Width per branch / subspace | D9: 48 | E9: 64 | F9: as source dataset | G9: All | H9: Each subspace or view = z_dim (DecVAE Z) | I9: Final
A10: S-09 | B10: Batch | C10: Batch size | D10: 16 utterances | E10: 8 utterances | F10: 8 utterances (fine-tuning) | G10: All | H10: SI Table 3 (about 1 min of audio). Same data exposure and update count for every method. | I10: Final
A11: S-10 | B11: Budget | C11: Max epochs (pre-training) | D11: 150 | E11: 150 | F11: 25 (fine-tuning) | G11: All | H11: Methods p.22 L536 | I11: Final
A12: S-11 | B12: Budget | C12: Early stopping | D12: own validation loss; warmup 100 epochs (28000 steps); patience 5; delta > 0.2% | E12: same (41568 steps) | F12: patience 5; warmup 50000 steps (check units) | G12: All | H12: Methods p.22 L534-536. Define warmup in epochs so it scales with batch. | I12: Final
... A19: S-18 | B19: Reproducibility | C19: Hardware | D19: single NVIDIA RTX 6000 Ada | E19: same | F19: same | G19: DecVAE | H19: Methods p.22 L530; record baselines' hardware too | I19: To confirm

Sheet Pre-training
A1: ID | B1: Method | C1: Group | D1: Parameter | E1: Config key | F1: Reference value | G1: Reference source | H1: SimVowels (agreed) | I1: TIMIT (agreed) | J1: SimVowels (config now) | K1: TIMIT (config now) | L1: Config check | M1: Deviation from reference | N1: Rationale / notes | O1: Status
A2: DV-01 | B2: DecVAE | C2: Input | D2: Input features | E2: input_type, n_mels, mel_hops, mel_norm | F2: (proposed method) | G2: Methods p.21 L546-548; SI Table 3 | H2: mel 80 bands, mel_hops 4 (80 x 5 = 400 per 25 ms frame), global norm | I2: mel 80 bands, mel_hops 4 (80 x 5 = 400 per 25 ms frame), global norm | L2: =IF(OR(J2="",K2=""),"n/a",IF(AND(H2&""=J2&"",I2&""=K2&""),"match","differs")) -> n/a | M2: n/a | N2: Mel outperforms waveform for all models (SI Tables 6-8). | O2: Final
A3: DV-02 | B3: DecVAE | C3: Architecture | D3: Latent dims (Z per subspace / S) | E3: z_latent_dim, s_latent_dim | F3: (proposed method) | G3: SI Table 3 | H3: 48 / 24 | I3: 64 / 32 | J3: 48 / 24 | K3: 64 / 32 | L3: =IF(OR(J3="",K3=""),"n/a",IF(AND(H3&""=J3&"",I3&""=K3&""),"match","differs")) -> match | M3: n/a | N3: Z subspace dim sets the baselines' per-branch width. | O3: Final
A4: DV-03 | B4: DecVAE | C4: Architecture | D4: Components (NoC) | E4: config name | F4: (proposed method) | G4: SI Table 3 | H4: 3 | I4: 4 | J4: 3 | K4: 4 | L4: =IF(OR(J4="",K4=""),"n/a",IF(AND(H4&""=J4&"",I4&""=K4&""),"match","differs")) -> match | M4: n/a | O4: Final
A5: DV-04 | B5: DecVAE | C5: Optimizer | D5: Optimizer | E5: adam_beta1/2, adam_epsilon | F5: (proposed method) | G5: Methods p.22 L534; config | H5: Adam (0.5, 0.999), eps 1e-6 | I5: Adam (0.5, 0.999), eps 1e-6 | J5: Adam (0.5, 0.999), eps 1e-6 | K5: Adam (0.5, 0.999), eps 1e-6 | L5: =IF(OR(J5="",K5=""),"n/a",IF(AND(H5&""=J5&"",I5&""=K5&""),"match","differs")) -> match | M5: n/a | O5: Final
A6: DV-05 | B6: DecVAE | C6: Optimizer | D6: Weight decay | E6: weight_decay | F6: (proposed method) | G6: config | H6: 0.0001 | I6: 0.0001 | J6: 0.0001 | K6: 0.0001 | L6: =IF(OR(J6="",K6=""),"n/a",IF(AND(H6&""=J6&"",I6&""=K6&""),"match","differs")) -> match | M6: n/a | O6: Final
A7: DV-06 | B7: DecVAE | C7: Optimizer | D7: Learning rate (Z / S) | E7: learning_rate | F7: (proposed method) | G7: Methods p.22 L531-533 | H7: 8e-5 / 1e-4 | I7: 8e-5 / 1e-4 | J7: 5e-5 / 1e-4 | K7: 8e-5 / 1e-4 | L7: =IF(OR(J7="",K7=""),"n/a",IF(AND(H7&""=J7&"",I7&""=K7&""),"match","differs")) -> differs | M7: n/a | N7: Paper states Z peak 8e-5; the SimVowels config holds 5e-5. Confirm which the reported SimVowels runs used. | O7: To confirm
A8: DV-07 | B8: DecVAE | C8: Schedule | D8: LR schedule (Z / S) | E8: lr_scheduler_type | F8: (proposed method) | G8: Methods p.22 L531-533 | H8: constant w/ warmup / linear | I8: constant w/ warmup / linear | J8: constant w/ warmup / linear | K8: constant w/ warmup / linear | L8: =IF(OR(J8="",K8=""),"n/a",IF(AND(H8&""=J8&"",I8&""=K8&""),"match","differs")) -> match | M8: n/a | O8: Final
A9: DV-08 | B9: DecVAE | C9: Schedule | D9: Warmup | E9: num_warmup_steps | F9: (proposed method) | G9: Methods p.22 L533 | H9: 5000 | I9: 8650 | J9: 5000 | K9: 8650 | L9: =IF(OR(J9="",K9=""),"n/a",IF(AND(H9&""=J9&"",I9&""=K9&""),"match","differs")) -> match | M9: n/a | O9: Final
A10: DV-09 | B10: DecVAE | C10: Optimizer | D10: Gradient clipping | E10: clip_grad_value | F10: (proposed method) | G10: config | H10: 2 | I10: 2 | J10: 2 | K10: 2 | L10: =IF(OR(J10="",K10=""),"n/a",IF(AND(H10&""=J10&"",I10&""=K10&""),"match","differs")) -> match | M10: n/a | O10: Final
A11: DV-10 | B11: DecVAE | C11: Batch | D11: Batch size (utterances) | E11: per_device_train_batch_size | F11: (proposed method) | G11: SI Table 3 | H11: 16 | I11: 8 | J11: 4 | K11: 1 | L11: =IF(OR(J11="",K11=""),"n/a",IF(AND(H11&""=J11&"",I11&""=K11&""),"match","differs")) -> differs | M11: n/a | N11: Paper and SI state 16 / 8 (about 1 min of audio). Local configs hold 4 / 1: confirm the reported runs used 16 / 8. | O11: To confirm
A12: DV-11 | B12: DecVAE | C12: Objective | D12: SSL frames used in loss | E12: mask_time_prob / ssl frames % | F12: (proposed method) | G12: SI Table 3 | H12: 50% | I12: 50% | J12: 50% | K12: 50% | L12: =IF(OR(J12="",K12=""),"n/a",IF(AND(H12&""=J12&"",I12&""=K12&""),"match","differs")) -> match | M12: n/a | N12: Reference point for TF-C's contrastive frame fraction. | O12: Final
A13: DV-12 | B13: DecVAE | C13: Budget | D13: Max epochs | E13: num_train_epochs | F13: (proposed method) | G13: Methods p.22 L536 | H13: 150 | I13: 150 | J13: 150 | K13: 150 | L13: =IF(OR(J13="",K13=""),"n/a",IF(AND(H13&""=J13&"",I13&""=K13&""),"match","differs")) -> match | M13: n/a | N13: Shared budget. | O13: Final
A14: DV-13 | B14: DecVAE | C14: Budget | D14: Early stopping | E14: early_stop_* | F14: (proposed method) | G14: Methods p.22 L534-536 | H14: 28000 / 5 / 0.2 | I14: 41568 / 5 / 0.2 | J14: 28000 / 5 / 0.2 | K14: 41568 / 5 / 0.2 | L14: =IF(OR(J14="",K14=""),"n/a",IF(AND(H14&""=J14&"",I14&""=K14&""),"match","differs")) -> match | M14: n/a | N14: Shared early-stopping rule. | O14: Final
A15: CO-01 | B15: CoST | C15: Input | D15: Input features | E15: cost_input_type, cost_pool_mel_bins, baseline_component | F15: Raw multivariate series | G15: Woo et al. 2022; salesforce/CoST | H15: mel, unpooled, 0 | I15: mel, unpooled, 0 | J15: mel, unpooled, 0 | K15: mel, unpooled, 0 | L15: =IF(OR(J15="",K15=""),"n/a",IF(AND(H15&""=J15&"",I15&""=K15&""),"match","differs")) -> match | M15: Yes | N15: Front-end held constant: DecVAE's input. | O15: Final
A16: CO-02 | B16: CoST | C16: Architecture | D16: Backbone hidden / depth | E16: cost_hidden_dims, cost_depth | F16: 64 / 10 | G16: cost.py L206-208 | H16: 64 / 10 | I16: 64 / 10 | J16: 64 / 10 | K16: 64 / 10 | L16: =IF(OR(J16="",K16=""),"n/a",IF(AND(H16&""=J16&"",I16&""=K16&""),"match","differs")) -> match | M16: No | O16: Final
A17: CO-03 | B17: CoST | C17: Architecture | D17: Trend kernels | E17: cost_kernels | F17: [1,2,4,8,16,32,64,128] | G17: train.py L43 | H17: [1,2,4,8,16,32,64,128] | I17: [1,2,4,8,16,32,64,128] | J17: [1,2,4,8,16,32,64,128] | K17: [1,2,4,8,16,32,64,128] | L17: =IF(OR(J17="",K17=""),"n/a",IF(AND(H17&""=J17&"",I17&""=K17&""),"match","differs")) -> match | M17: No | O17: Final
A18: CO-04 | B18: CoST | C18: Architecture | D18: Output dims (trend + season) | E18: cost_output_dims | F18: 320 | G18: train.py L34 (--repr-dims) | H18: 96 | I18: 128 | J18: 96 | K18: 128 | L18: =IF(OR(J18="",K18=""),"n/a",IF(AND(H18&""=J18&"",I18&""=K18&""),"match","differs")) -> match | M18: Yes | N18: Each subspace = z_dim (48 / 64), the latent-dimension rule. | O18: Final
A19: CO-05 | B19: CoST | C19: Objective | D19: Seasonal loss weight alpha | E19: cost_alpha | F19: 0.0005 | G19: train.py L44 | H19: 0.0005 | I19: 0.0005 | J19: 0.0005 | K19: 0.0005 | L19: =IF(OR(J19="",K19=""),"n/a",IF(AND(H19&""=J19&"",I19&""=K19&""),"match","differs")) -> match | M19: No | O19: Final
A20: CO-06 | B20: CoST | C20: Objective | D20: MoCo queue size K | E20: cost_queue_size | F20: 256 | G20: cost.py L240 | H20: 256 | I20: 256 | J20: 256 | K20: 256 | L20: =IF(OR(J20="",K20=""),"n/a",IF(AND(H20&""=J20&"",I20&""=K20&""),"match","differs")) -> match | M20: No | O20: Final
A21: CO-07 | B21: CoST | C21: Objective | D21: Key-encoder momentum m | E21: cost_momentum | F21: 0.999 | G21: cost.py L65 | H21: 0.999 | I21: 0.999 | J21: 0.999 | K21: 0.999 | L21: =IF(OR(J21="",K21=""),"n/a",IF(AND(H21&""=J21&"",I21&""=K21&""),"match","differs")) -> match | M21: No | O21: Final
A22: CO-08 | B22: CoST | C22: Objective | D22: Temperature T | E22: cost_temperature | F22: 0.07 | G22: cost.py L66 | H22: 0.07 | I22: 0.07 | J22: 0.07 | K22: 0.07 | L22: =IF(OR(J22="",K22=""),"n/a",IF(AND(H22&""=J22&"",I22&""=K22&""),"match","differs")) -> match | M22: No | O22: Final
A23: CO-09 | B23: CoST | C23: Augmentation | D23: Augmentation sigma / p | E23: cost_augmentation_sigma, _prob | F23: 0.5 / 0.5 | G23: cost.py L21-22 | H23: 0.5 / 0.5 | I23: 0.5 / 0.5 | J23: 0.5 / 0.5 | K23: 0.5 / 0.5 | L23: =IF(OR(J23="",K23=""),"n/a",IF(AND(H23&""=J23&"",I23&""=K23&""),"match","differs")) -> match | M23: No | O23: Final
A24: CO-10 | B24: CoST | C24: Training | D24: Timestamp mask | E24: cost_mask_mode; encoder calls | F24: binomial in training | G24: cost.py | H24: binomial (train); mask=None in encoder calls | I24: binomial (train); mask=None in encoder calls | L24: =IF(OR(J24="",K24=""),"n/a",IF(AND(H24&""=J24&"",I24&""=K24&""),"match","differs")) -> n/a | M24: No | O24: Final
A25: CO-11 | B25: CoST | C25: Training | D25: Padded frames | E25: encode() | F25: n/a (fixed-length series) | H25: removed before pooling, not zeroed | I25: removed before pooling, not zeroed | L25: =IF(OR(J25="",K25=""),"n/a",IF(AND(H25&""=J25&"",I25&""=K25&""),"match","differs")) -> n/a | M25: Yes | N25: TIMIT / IEMOCAP are variable length. | O25: To confirm
A26: CO-12 | B26: CoST | C26: Optimizer | D26: Optimizer | E26: cost_optimizer, cost_sgd_momentum | F26: SGD, momentum 0.9 | G26: cost.py L271-274 | H26: SGD, 0.9 | I26: SGD, 0.9 | J26: SGD, 0.9 | K26: SGD, 0.9 | L26: =IF(OR(J26="",K26=""),"n/a",IF(AND(H26&""=J26&"",I26&""=K26&""),"match","differs")) -> match | M26: No | O26: Final
A27: CO-13 | B27: CoST | C27: Optimizer | D27: Learning rate | E27: learning_rate | F27: 0.001 | G27: train.py L33 | H27: 0.001 | I27: 0.001 | J27: 0.001 | K27: 0.001 | L27: =IF(OR(J27="",K27=""),"n/a",IF(AND(H27&""=J27&"",I27&""=K27&""),"match","differs")) -> match | M27: No | O27: Final
A28: CO-14 | B28: CoST | C28: Optimizer | D28: Weight decay | E28: weight_decay | F28: 0.0001 | G28: cost.py L274 | H28: 0.0001 | I28: 0.0001 | J28: 0.0001 | K28: 0.0001 | L28: =IF(OR(J28="",K28=""),"n/a",IF(AND(H28&""=J28&"",I28&""=K28&""),"match","differs")) -> match | M28: No | O28: Final
A29: CO-15 | B29: CoST | C29: Schedule | D29: LR schedule | E29: lr_scheduler_type | F29: cosine to 0 over the run | G29: cost.py L443-447 | H29: cosine | I29: cosine | J29: cosine | K29: cosine | L29: =IF(OR(J29="",K29=""),"n/a",IF(AND(H29&""=J29&"",I29&""=K29&""),"match","differs")) -> match | M29: Yes | N29: Horizon is our budget instead of the reference's 200 / 600 iterations. | O29: Final
A30: CO-16 | B30: CoST | C30: Schedule | D30: Warmup | E30: num_warmup_steps | F30: none | G30: cost.py | H30: 0 | I30: 0 | J30: 0 | K30: 0 | L30: =IF(OR(J30="",K30=""),"n/a",IF(AND(H30&""=J30&"",I30&""=K30&""),"match","differs")) -> match | M30: No | O30: Final
A31: CO-17 | B31: CoST | C31: Optimizer | D31: Gradient clipping | E31: clip_grad_value | F31: none | G31: cost.py (no clipping) | H31: None | I31: None | J31: 1 | K31: 1 | L31: =IF(OR(J31="",K31=""),"n/a",IF(AND(H31&""=J31&"",I31&""=K31&""),"match","differs")) -> differs | M31: No | N31: No reference clips; clipping is part of the per-method optimizer. | O31: To fix
A32: CO-18 | B32: CoST | C32: Batch | D32: Batch size (utterances) | E32: per_device_train_batch_size | F32: 8 series | G32: train.py L32 | H32: 16 | I32: 8 | J32: 4 | K32: 128 | L32: =IF(OR(J32="",K32=""),"n/a",IF(AND(H32&""=J32&"",I32&""=K32&""),"match","differs")) -> differs | M32: Yes | N32: Shared batch (DecVAE). | O32: To fix
A33: CO-19 | B33: CoST | C33: Budget | D33: Training length | E33: num_train_epochs | F33: 200 / 600 iterations by data size | G33: cost.py L253-254 | H33: 150 | I33: 150 | J33: 150 | K33: 150 | L33: =IF(OR(J33="",K33=""),"n/a",IF(AND(H33&""=J33&"",I33&""=K33&""),"match","differs")) -> match | M33: Yes | N33: Shared budget. | O33: Final
A34: CO-20 | B34: CoST | C34: Budget | D34: Early-stopping warmup | E34: early_stop_warmup_steps | F34: n/a | H34: 28000 | I34: 41568 | J34: 10000 | K34: 10000 | L34: =IF(OR(J34="",K34=""),"n/a",IF(AND(H34&""=J34&"",I34&""=K34&""),"match","differs")) -> differs | M34: Yes | N34: 100 epochs at 16 / 8 utterances, as DecVAE. | O34: To fix
A35: TF-01 | B35: TF-C | C35: Input | D35: Input features | E35: tfc_input_type | F35: Raw univariate series, length 178 (SleepEEG) | G35: SleepEEG_Configs.py L18 | H35: waveform | I35: waveform | J35: waveform | K35: waveform | L35: =IF(OR(J35="",K35=""),"n/a",IF(AND(H35&""=J35&"",I35&""=K35&""),"match","differs")) -> match | M35: Yes | N35: Documented exception to the mel front-end: TF-C's frequency view is the FFT of a raw time series. | O35: Final
A36: TF-02 | B36: TF-C | C36: Input | D36: Sequence handling | E36: TFC.forward | F36: one series per sample | G36: model.py | H36: each frame one sample (sequence length 1) | I36: each frame one sample (sequence length 1) | L36: =IF(OR(J36="",K36=""),"n/a",IF(AND(H36&""=J36&"",I36&""=K36&""),"match","differs")) -> n/a | M36: Yes | N36: No temporal attention in the reference; frame grid kept. | O36: Final
A37: TF-03 | B37: TF-C | C37: Architecture | D37: Transformer layers / heads / FF | E37: tfc_transformer_layers, _attention_heads, _feedforward_multiplier | F37: 2 / 2 / 2 x d | G37: model.py L10-11 | H37: 2 / 2 / 2 | I37: 2 / 2 / 2 | J37: 2 / 2 / 2 | K37: 2 / 2 / 2 | L37: =IF(OR(J37="",K37=""),"n/a",IF(AND(H37&""=J37&"",I37&""=K37&""),"match","differs")) -> match | M37: No | O37: Final
A38: TF-04 | B38: TF-C | C38: Architecture | D38: Projector hidden | E38: tfc_projector_hidden | F38: 256 | G38: model.py L14 | H38: 256 | I38: 256 | J38: 256 | K38: 256 | L38: =IF(OR(J38="",K38=""),"n/a",IF(AND(H38&""=J38&"",I38&""=K38&""),"match","differs")) -> match | M38: No | O38: Final
A39: TF-05 | B39: TF-C | C39: Architecture | D39: Projector output (each view) | E39: tfc_projector_dim | F39: 128 | G39: model.py L17 | H39: 48 | I39: 64 | J39: 48 | K39: 48 | L39: =IF(OR(J39="",K39=""),"n/a",IF(AND(H39&""=J39&"",I39&""=K39&""),"match","differs")) -> differs | M39: Yes | N39: Each view = z_dim. TIMIT config holds 48. | O39: To fix
A40: TF-06 | B40: TF-C | C40: Objective | D40: NT-Xent temperature | E40: tfc_temperature | F40: 0.2 | G40: SleepEEG_Configs.py L52 | H40: 0.2 | I40: 0.2 | J40: 0.2 | K40: 0.2 | L40: =IF(OR(J40="",K40=""),"n/a",IF(AND(H40&""=J40&"",I40&""=K40&""),"match","differs")) -> match | M40: No | O40: Final
...

Sheet Fine-tuning
A1: ID | B1: Method | C1: Parameter | D1: Config key | E1: Value | F1: Config now | G1: Rule / rationale | H1: Status
A2: F-01 | B2: All | C2: Transfer sources | D2: transfer_from | E2: SimVowels and TIMIT checkpoints | F2: timit / sim_vowels | G2: Both transfers reported for every method. | H2: Final
A3: F-02 | B3: All | C3: Epochs | D3: num_train_epochs | E3: 25 | F3: 25 | G3: Shared. | H3: Final
A4: F-03 | B4: All | C4: Batch size (utterances) | D4: per_device_train_batch_size | E4: 8 | F4: 8 | G4: Shared. | H4: Final
A5: F-04 | B5: All | C5: Early-stopping warmup | D5: early_stop_warmup_steps | E5: same rule for all methods | F5: 50000 | G5: 50000 steps exceeds 25 epochs on most IEMOCAP splits; express in epochs. | H5: To confirm
A6: F-05 | B6: Baselines | C6: Gradient clipping | D6: clip_grad_value | E6: None | F6: 1 | G6: No reference clips. | H6: To fix
A7: F-06 | B7: DecVAE | C7: Learning rate (Z / S) | D7: learning_rate | E7: 5e-6 / 5e-6 | F7: 5e-6 / 5e-6 | H7: Final
A8: F-07 | B8: DecVAE | C8: Latent dims when transferring from TIMIT | D8: z_latent_dim, s_latent_dim | E8: 64 / 32 | F8: 48 / 24 | G8: Fine-tune config holds 48 / 24 with transfer_from = timit. | H8: To confirm
A9: F-08 | B9: CoST | C9: Learning rate | D9: learning_rate | E9: 0.0001 | F9: 0.0001 | G9: 0.1 x pre-training LR. | H9: Final
A10: F-09 | B10: CoST | C10: Re-initialized parts | D10: cost_transfer_reinit_fourier | E10: Fourier layer (sequence-length dependent) | F10: True | H10: Final
A11: F-10 | B11: TF-C | C11: Learning rate | D11: learning_rate | E11: 3e-05 | F11: 3e-05 | G11: 0.1 x pre-training LR. | H11: Final
A12: F-11 | B12: TCL | C12: Learning rate | D12: learning_rate | E12: 0.001 | F12: 0.001 | G12: 0.1 x pre-training LR. | H12: Final
A13: F-12 | B13: TCL | C13: Re-initialized parts | D13: tcl_transfer_reinit_classifier | E13: segment classifier (class count changes) | F13: True | H13: Final
A14: F-13 | B14: CPC | C14: Learning rate | D14: learning_rate | E14: 2e-05 | F14: 2e-05 | G14: 0.1 x pre-training LR. | H14: Final
A15: F-14 | B15: CPC | C15: Re-initialized parts | D15: cpc_transfer_reinit_predictors | E15: none (nothing sized by frame count) | F15: False | H15: Final
A16: F-15 | B16: FHVAE | C16: Learning rate | D16: learning_rate | E16: 0.0001 | G16: 0.1 x pre-training LR. | H16: To implement
A17: F-16 | B17: FHVAE | C17: mu table | D17: (model) | E17: rebuilt for IEMOCAP training utterances | G17: The table is transductive: one row per training utterance. | H17: To implement
A18: F-17 | B18: FHVAE | C18: Config files | D18: config_finetune_fhvae_iemocap_* | E18: from SimVowels and from TIMIT | F18: missing | H18: To implement

Sheet Evaluation
A1: ID | B1: Method | C1: Branch | D1: Parameter | E1: Config key | F1: SimVowels | G1: TIMIT | H1: IEMOCAP | I1: Rationale / notes | J1: Status
A2: E-01 | B2: All | C2: Z | D2: Disentanglement metrics | E2: measure_disentanglement, sup_eval | F2: MI (adjusted, pairwise), GCN, DCI (gradient boosting), modularity, explicitness, IRS | G2: same | H2: same | I2: Posterior means / deterministic outputs. | J2: Final
A3: E-02 | B3: All | C3: Z | D3: Factors | E3: classification_tasks | F3: vowel, speaker_frame | G3: phoneme, speaker_frame | H3: phoneme, speaker_frame, emotion_frame | J3: Final
A4: E-03 | B4: All | C4: Z | D4: Label overlaps | E4: discard_label_overlaps | F4: True | G4: True | H4: True | J4: Final
A5: E-04 | B5: All | C5: Z | D5: Disentanglement CV splits | E5: disentanglement_eval_cv_splits | F5: 1 | G5: 5 | H5: 5 | J5: Final
A6: E-05 | B6: All | C6: Z, S | D6: Classification CV splits | E6: classif_eval_cv_splits | F6: 5 | G6: 5 | H6: 5 | J6: Final
A7: E-06 | B7: All | C7: Z, S | D7: Random states | E7: random_states | F7: DecVAE 10; trained baselines 1 | G7: 5 (all) | H7: DecVAE / SSL / PCA / SFA 10; trained baselines 1 | I7: Must match across methods. | J7: To fix
A8: E-07 | B8: All | C8: Z, S | D8: Classification | E8: classify | F8: True | G8: False (no TIMIT classification results) | H8: True | I8: TIMIT reports disentanglement only. | J8: Final
A9: E-08 | B9: All | C9: S | D9: Sequence tasks | E9: classification_tasks | F9: speaker_seq | G9: none | H9: speaker_seq, emotion_seq | I9: One factor: accuracy only, no disentanglement metrics. | J9: Final
A10: E-09 | B10: All | C10: S | D10: Sequence readout rule | E10: *_seq_pooling | F10: mean over frames (unmasked, as DecVAE's AdaptiveAvgPool1d) | G10: n/a | H10: same | I10: Exception: FHVAE uses its s-vector. On IEMOCAP the unmasked mean also carries length. | J10: Final
A11: E-10 | B11: DecVAE | C11: Z | D11: Frame representation | F11: concatenated subspaces (C + 1) x 48 | G11: (C + 1) x 64 | H11: as source | J11: Final
A12: E-11 | B12: DecVAE | C12: S | D12: Sequence representation | F12: S latent (24) | G12: S latent (32) | H12: as source | J12: Final
A13: E-12 | B13: CoST | C13: Z | D13: Frame representation | E13: cost_representation | F13: trend + season (both), 96 | G13: both, 128 | H13: both | J13: Final
A14: E-13 | B14: CoST | C14: S | D14: Sequence pooling | E14: cost_seq_pooling | F14: mean | G14: n/a | H14: mean | J14: Final
A15: E-14 | B15: TF-C | C15: Z | D15: Frame representation | E15: tfc_representation | F15: z_time + z_freq projector outputs, 96 | G15: both, 128 | H15: both | I15: model.eval() for BatchNorm. | J15: Final
A16: E-15 | B16: TF-C | C16: S | D16: Sequence pooling | E16: tfc_seq_pooling | F16: mean | G16: n/a | H16: mean | J16: Final
A17: E-16 | B17: TCL | C17: Z | D17: Frame representation | E17: (last hidden layer) | F17: abs features, 48 | G17: 64 | H17: as source | I17: Evaluate EMA-averaged weights (reference). | J17: To implement
A18: E-17 | B18: TCL | C18: S | D18: Sequence pooling | E18: tcl_seq_pooling | F18: mean | G18: n/a | H18: mean | J18: Final
A19: E-18 | B19: CPC | C19: Z | D19: Frame representation (headline) | E19: cpc_representation | F19: context c, 48 | G19: context c, 64 | H19: context c | J19: Final
A20: E-19 | B20: CPC | C20: Z | D20: Frame representation (secondary) | E20: cpc_representation | F20: encoder z (post-ReLU) | G20: encoder z | H20: encoder z | I20: Fixed in advance; z is non-Gaussian (about 50% zeros). | J20: To confirm
A21: E-20 | B21: CPC | C21: S | D21: Sequence pooling | E21: cpc_seq_pooling | F21: mean (not last frame) | G21: n/a | H21: mean | I21: The last frame is not trained to summarize the utterance. | J21: Final
A22: E-21 | B22: FHVAE | C22: Z | D22: Frame representation (headline) | E22: fhvae_representation | F22: [mu_seg ; mu_seq], shift-1 centred windows, 96 | G22: same, 128 | H22: same | I22: Reference frame readout (get_frame_ra_dataset_conf, _pad_feats). | J22: Final
A23: E-22 | B23: FHVAE | C23: Z | D23: Frame representation (secondary) | E23: fhvae_representation | F23: mu_seg only | G23: mu_seg only | H23: mu_seg only | I23: Shows speaker leakage into the segment latent. | J23: Final
A24: E-23 | B24: FHVAE | C24: S | D24: Sequence representation | E24: fhvae_seq_pooling | F24: s-vector mu_hat = sum mu_seq / (N + 0.25), non-overlapping segments | G24: n/a | H24: same | I24: Reference dump_repr (which_repr = mu1). | J24: Final
A25: E-24 | B25: FHVAE | C25: Z | D25: Padding mask passed to encode | E25: post-analysis | F25: needed | G25: needed | H25: needed | I25: Windows must not read padded frames. | J25: To confirm
A26: E-25 | B26: Frozen SSL | C26: Z / S | D26: Branches evaluated | F26: Z only | G26: Z only | H26: Z + S | J26: Final
A27: E-26 | B27: Frozen SSL | C27: Z | D27: Layer / reduction | E27: ssl_hidden_layer, ssl_pca_components | F27: last layer, no PCA | G27: same | H27: same | I27: No PCA / ICA on SSL embeddings. | J27: Final

Sheet Tracker
A1: # | B1: Item | C1: Method | D1: Where | E1: Action | F1: Linked ID | G1: Priority | H1: Status
A2: 1 | B2: MLR stage longer than the whole run | C2: TCL | D2: tcl_args / tcl.py train_steps | E2: Separate classifier-only stage of 10% of the main stage, then main stage; decay at 5/7 of main stage. | F2: TC-06, TC-07 | G2: Critical | H2: Open
A3: 2 | B3: No EMA weights for evaluation | C3: TCL | D3: tcl.py / trainer / post-analysis | E3: Keep EMA 0.999 of weights; evaluate the averaged weights. | F3: TC-08, E-16 | G3: High | H3: Open
A4: 3 | B4: Batch sizes not at 16 / 8 | C4: All baselines | D4: pre-training configs | E4: Set per_device_train_batch_size 16 (SimVowels) / 8 (TIMIT). | F4: CO/TF/TC/CP/FH batch rows | G4: High | H4: Open
A5: 4 | B5: Early-stopping warmup 10000 steps | C5: All baselines | D5: pre-training configs | E5: Set 28000 / 41568 (100 epochs at 16 / 8) or define in epochs. | F5: S-11 | G5: High | H5: Open
A6: 5 | B6: Gradient clipping 1.0 | C6: CoST, TF-C, TCL, CPC | D6: pre-training and fine-tuning configs | E6: Set clip_grad_value to None. | F6: S-16, F-05 | G6: High | H6: Open
A7: 6 | B7: TF-C epochs 40 | C7: TF-C | D7: pre-training configs | E7: Set num_train_epochs 150. | F7: TF-19 | G7: High | H7: Open
A8: 7 | B8: TF-C TIMIT projector 48 | C8: TF-C | D8: config_pretraining_tfc_timit.json | E8: Set tfc_projector_dim 64. | F8: TF-05 | G8: High | H8: Open
A9: 8 | B9: Evaluation random_states differ | C9: All | D9: latent_evaluations configs | E9: Use one value per dataset for every method. | F9: E-06 | G9: High | H9: Open
A10: 9 | B10: Subset caches for trained baselines | C10: All baselines | D10: TIMIT / IEMOCAP configs | E10: Point final runs at the full caches used by DecVAE. | F10: S-04 | G10: High | H10: Open
A11: 10 | B11: TF-C contrastive frames as a fraction | C11: TF-C | D11: tfc.py sampler | E11: Sample 50% of each utterance's valid frames instead of a fixed count (TIMIT). | F11: TF-11 | G11: Medium | H11: Open
A12: 11 | B12: CPC g_enc hidden 256 | C12: CPC | D12: cpc configs | E12: Confirm 512 (reference and DecVAE). | F12: CP-03 | G12: Medium | H12: Open
A13: 12 | B13: CPC encoder norm | C13: CPC | D13: cpc configs | E13: Confirm ChannelNorm (CPC_audio) vs none (Spijkervet). | F13: CP-05 | G13: Low | H13: Open
... A20: 19 | B20: Checkpoint evaluated | C20: All | D20: latent_evaluations configs | E20: Confirm last vs min-val-loss checkpoint, same for all methods. | F20: S-12 | G20: Medium | H20: Open
