Workbook

Sheet Overview
A1: DecVAE revision tracker
A2: npj Artificial Intelligence, submission c86c5415-7be3-43e1-8a57-9b3e782755ae
A4: Update the Status column on each sheet. The counts below follow automatically.
A6: Reviewer comments
A7: Status | B7: Count
A8: Not started | B8: =COUNTIF(Comments!G:G,"Not started") -> 21
A9: Planned | B9: =COUNTIF(Comments!G:G,"Planned") -> 0
A10: In progress | B10: =COUNTIF(Comments!G:G,"In progress") -> 12
A11: Blocked | B11: =COUNTIF(Comments!G:G,"Blocked") -> 1
A12: Done | B12: =COUNTIF(Comments!G:G,"Done") -> 2
A13: Dropped | B13: =COUNTIF(Comments!G:G,"Dropped") -> 0
A14: Optional | B14: =COUNTIF(Comments!G:G,"Optional") -> 0
A15: Total | B15: =COUNTA(Comments!A:A)-2 -> 36
A18: Experiments and analyses
A19: Status | B19: Count
A20: Not started | B20: =COUNTIF(Experiments!G:G,"Not started") -> 8
A21: Planned | B21: =COUNTIF(Experiments!G:G,"Planned") -> 7
A22: In progress | B22: =COUNTIF(Experiments!G:G,"In progress") -> 0
A23: Blocked | B23: =COUNTIF(Experiments!G:G,"Blocked") -> 0
A24: Done | B24: =COUNTIF(Experiments!G:G,"Done") -> 0
A25: Dropped | B25: =COUNTIF(Experiments!G:G,"Dropped") -> 2
A26: Optional | B26: =COUNTIF(Experiments!G:G,"Optional") -> 2
A27: Total | B27: =COUNTA(Experiments!A:A)-2 -> 19
A30: Writing tasks
A31: Status | B31: Count
A32: Not started | B32: =COUNTIF(Writing!E:E,"Not started") -> 22
A33: Planned | B33: =COUNTIF(Writing!E:E,"Planned") -> 0
A34: In progress | B34: =COUNTIF(Writing!E:E,"In progress") -> 2
A35: Blocked | B35: =COUNTIF(Writing!E:E,"Blocked") -> 2
A36: Done | B36: =COUNTIF(Writing!E:E,"Done") -> 0
A37: Dropped | B37: =COUNTIF(Writing!E:E,"Dropped") -> 0
A38: Optional | B38: =COUNTIF(Writing!E:E,"Optional") -> 0
A39: Total | B39: =COUNTA(Writing!A:A)-2 -> 26
A42: Open decisions
A43: Status | B43: Count
A44: Not started | B44: =COUNTIF(Decisions!E:E,"Not started") -> 0
A45: Planned | B45: =COUNTIF(Decisions!E:E,"Planned") -> 0
A46: In progress | B46: =COUNTIF(Decisions!E:E,"In progress") -> 0
A47: Blocked | B47: =COUNTIF(Decisions!E:E,"Blocked") -> 7
A48: Done | B48: =COUNTIF(Decisions!E:E,"Done") -> 0
...

Sheet Comments
A1: Reviewer comments (35 comments + editor)
A3: ID | B3: Reviewer | C3: Severity | D3: Comment | E3: Type | F3: Master response | G3: Status | H3: Priority | I3: Notes
A4: Editor | B4: Editor | C4: - | D4: Four themes: framing, baselines, disentanglement evidence, presentation | E4: Umbrella | F4: MR-A/B/D | G4: In progress | H4: High | I4: Cover letter drafted
A5: R1 #1 | B5: R1 | C5: Minor | D5: Autoencoder naming: relabel or rename | E5: Text | F5: MR-A | G5: In progress | H5: High | I5: Adopting R1's relabel option; keep DecVAE. Do NOT use the PCA/ICA precedent argument
A6: R1 #2 | B6: R1 | C6: Minor | D6: Discuss compactness and deployment trade-off | E6: Text | F6: - | G6: Not started | H6: Medium | I6: Quantify dimensionality vs VAE baselines
A7: R1 #3 | B7: R1 | C7: Minor | D7: Intuition for adversarial stabilisation in main text | E7: Text | F7: MR-B | G7: Not started | H7: Medium | I7: Consider adding KL collapse curves
A8: R1 #4 | B8: R1 | C8: Minor | D8: Notation mapping table, main vs supplement | E8: Text | F8: - | G8: Not started | H8: Medium | I8: Z-tilde / z_c-tilde vs h_i / Z^k, and h = w^-1(z)
A9: R1 #5 | B9: R1 | C9: Major | D9: Sequence-based or contrastive baselines | E9: Experiment | F9: MR-D | G9: In progress | H9: High | I9: Covered by TCL, SFA, SlowVAE, FHVAE
A10: R1 #6 | B10: R1 | C10: - | D10: Beta sensitivity vs orthogonality and accuracy | E10: Analysis | F10: - | G10: Not started | H10: Medium | I10: Beta curve with accuracy and GCN at the same time
A11: R2 | B11: R2 | C11: Minor | D11: Proofread; expand figure captions | E11: Text | F11: - | G11: Not started | H11: Low | I11: Figs 1, 2, 6 most likely
A12: R3 #1 | B12: R3 | C12: Major | D12: TCL and CoST in at least one task | E12: Experiment | F12: MR-D | G12: In progress | H12: High | I12: Running on two datasets, not one
A13: R3 #2 | B13: R3 | C13: Major | D13: FD fixed frequency boundaries and generalisability | E13: Text | F13: MR-E | G13: Not started | H13: High | I13: Position: boundaries are a per-signal-class hyperparameter
A14: R3 #3 | B14: R3 | C14: Minor | D14: Unresolved citation, line 499 | E14: Text | F14: - | G14: Done | H14: Low | I14: Resolves correctly in current draft; reviewer saw an earlier compile
... A39: R6 #3 | B39: R6 | C39: Major/Minor | D39: Eq. (9) not shown to be a bound; sign conventions | E39: Text | F39: MR-B | G39: In progress | H39: High | I39: Correct in every particular; drove the main revision

Sheet Experiments
A1: Experiments and analyses, in priority order
A3: Rank | B3: Item | C3: Category | D3: Datasets | E3: GPU runs | F3: Closes | G3: Status | H3: Notes
A4: 1 | B4: wav2vec2 frozen embeddings (optionally WavLM) | C4: Baseline | D4: SimVowels, TIMIT, IEMOCAP | E4: 0 (inference) | F4: R5 #2 | G4: Planned | H4: Zero pre-training. Encoder is already Wav2Vec2-based, so this is a same-encoder/different-objective control
A5: 2 | B5: Slow Feature Analysis (SFA) | C5: Baseline | D5: SimVowels, TIMIT, IEMOCAP | E5: 0 (CPU) | F5: R1 #5 | G5: Planned | H5: sklearn-sfa. Needs ordered contiguous frames. Use context stacking or quadratic expansion. Run at 20 comps and at z_dim
A6: 3 | B6: CoST | C6: Baseline | D6: SimVowels, TIMIT | E6: 2 | F6: R3 #1, R5 #2 | G6: Planned | H6: Run first of the GPU jobs: most dangerous comparison, want the result early
A7: 4 | B7: TCL | C7: Baseline | D7: SimVowels, TIMIT | E7: 2 | F7: R1 #5, R3 #1 | G7: Planned | H7: Small MLP with segment-index pretext. Best Major-comments-per-GPU-hour on the list
A8: 5 | B8: FHVAE | C8: Baseline | D8: SimVowels, TIMIT | E8: 2 | F8: R1 #5, R5 #2 | G8: Planned | H8: Zero protocol invention; originally evaluated on TIMIT with the same two-timescale structure
A9: 6 | B9: CPC | C9: Baseline | D9: TIMIT | E9: 1 | F9: R5 #2 | G9: Planned | H9: Named by R5 explicitly; cheap. Completes R5's five-family list
A10: 7 | B10: IEMOCAP carry-forward (best 2 of ranks 3-5) | C10: Baseline | D10: IEMOCAP | E10: 2 | F10: R4 #1, R5 #6 | G10: Planned | H10: Hardest case for the frequency prior, so the most informative win
A11: 8 | B11: TF-C | C11: Baseline | D11: SimVowels, TIMIT | E11: 2 | F11: R5 #2 | G11: Optional | H11: Requested by nobody but the sharpest test: one frequency view vs C orthogonal components
A12: 9 | B12: SlowVAE | C12: Baseline | D12: SimVowels (TIMIT if budget) | E12: 1-2 | F12: R1 #5 | G12: Optional | H12: SimVowels first: its identifiability claim needs ground-truth factors
A13: 10 | B13: DSVAE | C13: Baseline | D13: - | E13: - | F13: R5 #2 | G13: Dropped | H13: Same reviewer slot as FHVAE, more protocol invention
A14: 11 | B14: BTSF | C14: Baseline | D14: - | E14: - | F14: R5 #2 | G14: Dropped | H14: Same slot as TF-C, less pointed comparison
A15: 12 | B15: New synthetic data: non-frequency, mixed, correlated factors | C15: Simulation | D15: New | E15: TBD | F15: R5 #6, R4 #1 | G15: Not started | H15: Plan jointly with the baseline grid. See decision D3
... A22: 19 | B22: Metric robustness under label noise and factor imbalance | C22: Analysis | D22: Existing latents | E22: 0 | F22: R5 #7 | G22: Not started | H22: No pre-training needed; perturb labels and re-run the metric suite

Sheet Writing
A1: Manuscript writing and correction tasks
A3: ID | B3: Task | C3: Where | D3: Linked to | E3: Status | F3: Notes
A4: W1 | B4: Definitional paragraph: latent-level autoencoding; rate term without sampling | C4: Introduction + Methods | D4: MR-A, R1 #1, R5 #1 | E4: In progress | F4: Draft written, needs placing and final wording
A5: W2 | B5: Rewrite SI Section 5: retitle, rescope, state what is and is not bounded | C5: SI Sec. 5 | D5: MR-B | E5: Not started | F5: Keep the derivation as motivation, correctly scoped
A6: W3 | B6: Unify sign conventions across Eq. (1), Eq. (9), SI Eq. (12), Alg. 1 | C6: Main + SI | D6: MR-B, R6 #3 | E6: Not started | F6: Code minimises L_recon + L_ortho + beta*L_prior
A7: W4 | B7: Separate symbols: D_recon/D_ortho for measures, L_recon/L_ortho for losses | C7: Main + SI | D7: MR-B, R6 #3 | E7: Not started | F7: This is the real source of the sign confusion
A8: W5 | B8: Fix SI Alg. 2 line 31: negative CE is -log(JSD), not -log(1-JSD) | C8: SI Alg. 2 | D8: MR-B, R6 #3 | E8: Not started | F8: Code uses BCE with target 1 for negatives
A9: W6 | B9: Withdraw the FactorVAE analogy | C9: Main l.431, SI l.112 | D9: MR-B | E9: Not started | F9: FactorVAE subtracts a term it minimises; our case is the mirror image
A10: W7 | B10: Rename the objective | C10: Throughout | D10: MR-B | E10: Blocked | F10: See decision D2. 'DELBO-inspired' is dropped either way
A11: W8 | B11: Equilibrium proposition as the positive theoretical content | C11: SI Sec. 5 or 7 | D11: MR-B | E11: Not started | F11: Replaces the lost bound; connects to the SVD/PCA argument. Decision D7
A12: W9 | B12: Restate Eqs. (4b), (5) and (7) | C12: Methods | D12: MR-C, R5 #13, R6 #1 | E12: Not started | F12: Marginal of a sum vs joint of independents; invalid posterior factorisation
A13: W10 | B13: Reconcile p(z) pushforward vs the isotropic prior; scope Assumption 1 | C13: SI Sec. 5 | D13: MR-C | E13: Not started | F13: Two different objects used interchangeably
A14: W11 | B14: Notation mapping table, main text vs supplement | C14: Main + SI | D14: R1 #4 | E14: Not started
A15: W12 | B15: Remove 'chromagram-guided dynamics' | C15: Main l.92 | D15: R5 #5 | E15: Not started | F15: Single occurrence; not in SI or code
A16: W13 | B16: Fix spacing at lines 508 and 736; full typography sweep | C16: Main | D16: R3 #4 | E16: In progress
A17: W14 | B17: Sweep for unresolved references and formatting artefacts | C17: Main + SI | D17: R3 #3, R4 #6 | E17: Not started | F17: Both already resolve, but state that a sweep was done
A18: W15 | B18: Compactness and deployment trade-off in the Discussion | C18: Discussion | D18: R1 #2 | E18: Not started
A19: W16 | B19: Two or three sentences on adversarial stabilisation and collapse | C19: Methods | D19: R1 #3 | E19: Not started
A20: W17 | B20: State that orthogonality here means distributional separation | C20: Methods | D20: R4 #4 | E20: Not started | F20: Cite MI and GCN results as evidence, not as construction
A21: W18 | B21: Signpost DecAE (beta = 0) as the non-variational ablation | C21: Results / SI | D21: R5 #12 | E21: Not started | F21: Give the specific table and figure numbers
A22: W19 | B22: Precise padding and random concatenation procedure | C22: Alg. 1 | D22: R6 #2 | E22: Not started | F22: Say whether concatenation is within-speaker and how labels are assigned
A23: W20 | B23: Assess and place the three suggested citations | C23: Discussion | D23: R5 #15 | E23: Not started | F23: See decision D5
A24: W21 | B24: Cite and distinguish LaST, Autoformer, FEDformer, SpeechSplit | C24: Intro / Related work | D24: MR-D | E24: Not started | F24: Autoformer is not currently cited at all; FEDformer is [38]
A25: W22 | B25: Move the CPC citation [2] out of the dysarthria sentence | C25: Main l.29 | D25: - | E25: Not started | F25: Currently cited as support for dysarthric speech recognition
A26: W23 | B26: Abstract: soften 'extends VAEs'; gloss 'encoder-only' | C26: Abstract | D26: MR-A | E26: Not started | F26: 'variational prior approximation' is already accurate; light touch only
A27: W24 | B27: Expand figure captions | C27: Figs. 1, 2, 6 | D27: R2 | E27: Not started
A28: W25 | B28: Full proofreading pass | C28: Whole manuscript | D28: R2 | E28: Not started
A29: W26 | B29: Narrow modality claims, or report the new modality | C29: Abstract + Discussion | D29: R5 #4 | E29: Blocked | F29: See decision D1

Sheet Decisions
A1: Open decisions (only you can settle these)
A3: ID | B3: Decision | C3: Linked to | D3: Impact | E3: Status | F3: Resolution
A4: D1 | B4: Narrow the claim to speech-like signals, or add a non-speech modality (EEG/ECG) | C4: R5 #4, W26 | D4: High | E4: Blocked
A5: D2 | B5: Final name for the objective: redefine DELBO, or L_dec | C5: MR-B, W7 | D5: Medium | E5: Blocked
A6: D3 | B6: Run baselines on the new synthetic dataset as well | C6: R5 #6, MR-E, Exp 12 | D6: High | E6: Blocked
A7: D4 | B7: Benchmark SpeechSplit, or cite it only | C7: MR-D | D7: Low | E7: Blocked
A8: D5 | B8: Are R5's three suggested citations genuinely relevant | C8: R5 #15, W20 | D8: Low | E8: Blocked
A9: D6 | B9: Presentation of changes: tracked changes, colour, or separate marked-up file | C9: Submission | D9: Low | E9: Blocked
A10: D7 | B10: Include the equilibrium proposition in the supplement | C10: MR-B, W8 | D10: Medium | E10: Blocked
